import { Request, Response, NextFunction } from 'express';
import logger from '../utils/logger';

export class AppError extends Error {
  public readonly statusCode: number;
  public readonly code: string;
  public readonly isOperational: boolean;

  constructor(message: string, statusCode: number = 500, code: string = 'INTERNAL_ERROR') {
    super(message);
    this.statusCode = statusCode;
    this.code = code;
    this.isOperational = true;

    Error.captureStackTrace(this, this.constructor);
  }
}

export const errorHandler = (
  err: Error | AppError,
  req: Request,
  res: Response,
  next: NextFunction
): void => {
  if (err instanceof AppError) {
    logger.error(`AppError: ${err.message}`, {
      code: err.code,
      statusCode: err.statusCode,
      path: req.path,
      method: req.method,
      userId: (req as any).userId,
    });

    res.status(err.statusCode).json({
      success: false,
      error: {
        message: err.message,
        code: err.code,
      },
    });
    return;
  }

  // Handle unexpected errors
  logger.error('Unexpected error:', {
    error: err.message,
    stack: err.stack,
    path: req.path,
    method: req.method,
  });

  res.status(500).json({
    success: false,
    error: {
      message: 'An unexpected error occurred',
      code: 'INTERNAL_ERROR',
    },
  });
};

export const notFoundHandler = (req: Request, res: Response): void => {
  res.status(404).json({
    success: false,
    error: {
      message: `Route ${req.method} ${req.path} not found`,
      code: 'ROUTE_NOT_FOUND',
    },
  });
};

export const asyncHandler = (
  fn: (req: Request, res: Response, next: NextFunction) => Promise<any>
) => {
  return (req: Request, res: Response, next: NextFunction) => {
    Promise.resolve(fn(req, res, next)).catch(next);
  };
};
